<?xml version="1.0"?>

<robot xmlns:xacro="http://ros.org/wiki/xacro" name="robot_essentials" >

  <!--######################################################################-->
  <xacro:macro name="wheel" params="prefix reflect mass radius length">
    <!-- LINK -->
    <link name="${prefix}_wheel">
      <inertial>
        <origin xyz="0 0 0" rpy="0 0 0" />
        <mass value="${mass}" />
        <inertia
          ixx="${0.0833333 * mass * (3 * radius * radius + length * length)}" 
          ixy="0.0" 
          ixz="0.0"
          iyy="${0.0833333 * mass * (3 * radius * radius + length * length)}" 
          iyz="0.0"
          izz="${0.5 * mass * radius * radius}" />
      </inertial>
      <visual>
        <origin
          xyz="0 0 0"
          rpy="0 0 ${0.5*pi*(reflect+1)}" />
        <geometry> 
          <mesh filename="package://bogbot_description/meshes/wheel_bogbot.dae" /> 
        </geometry>
      </visual>
      <collision>
        <origin
          xyz="0 0 0"
          rpy="${pi/2} 0 0" />
        <geometry>
          <cylinder length="${length}" radius="${radius}"/>
        </geometry>
      </collision>
    </link>

    <!--JOINT-->
    <joint name="${prefix}_wheel_joint" type="continuous">
      <axis xyz="0 1 0"/>
      <parent link ="base_link"/>
      <child link ="${prefix}_wheel"/>
      <origin rpy ="0 0 0" xyz= "-0.01 ${reflect*0.29} -0.05"/>
    </joint>

    <!--TRANSMISSION -->
    <transmission name="${prefix}_wheel_trans" type="SimpleTransmission">
      <type>transmission_interface/SimpleTransmission</type>
      <actuator name="${prefix}_wheel_motor">
        <hardwareInterface>hardware_interface/VelocityJointInterface</hardwareInterface>
        <mechanicalReduction>1</mechanicalReduction>
      </actuator>
      <joint name="${prefix}_wheel_joint">
        <hardwareInterface>hardware_interface/VelocityJointInterface</hardwareInterface>
      </joint>
    </transmission>

  </xacro:macro>
    
  <!-- Macro for defining caster wheels -->
  <xacro:macro name="caster_wheel" params="prefix reflect radius">
    <link name="${prefix}_caster_wheel">
      <visual>
        <origin xyz="-0.4365 ${reflect*0.23} -0.025" rpy="0 0 ${-reflect*pi/4}" />
        <geometry> 
          <mesh filename="package://bogbot_description/meshes/caster_wheel.dae" /> 
        </geometry>
      </visual>
      <collision>
        <origin xyz="-0.4365 ${reflect*0.25} -0.06" rpy="0 0 0" />
        <geometry>
          <sphere radius="${radius}"/>
        </geometry>
      </collision>
    </link>
    <joint name="${prefix}_caster_wheel_joint" type="fixed">
      <parent link="base_link"/>
      <child link="${prefix}_caster_wheel"/>
    </joint>
  </xacro:macro>
</robot>
